<sdf version='1.7'>
  <world name='default'>
    <plugin name='cleaner_world' filename='libworld_control_plugin.so'>
      <physics type="ode" name="unthrottled" default="true">
        <real_time_update_rate>5000.0</real_time_update_rate>
        <real_time_factor>1.0</real_time_factor>
        <max_step_size>0.0002</max_step_size>
        <ode>
          <solver>
            <thread_position_correction>1</thread_position_correction>
            <island_threads>10</island_threads>
            <iters>400</iters>
            <sor>0.1</sor>
          </solver>
          <constraints>
            <erp>0.01</erp>
          </constraints>
        </ode>
      </physics>
    </plugin>
    <model name='ground_plane'>
      <static>1</static>
      <link name='link'>
        <collision name='collision'>
          <geometry>
            <plane>
              <normal>0 0 1</normal>
              <size>100 100</size>
            </plane>
          </geometry>
          <surface>
            <friction>
              <ode>
                <mu>10000</mu>
                <mu2>10000</mu2>
                <fdir1>0 0 0</fdir1>
                <slip1>0</slip1>
                <slip2>0</slip2>
              </ode>
              <torsional>
                <coefficient>1</coefficient>
                <patch_radius>0</patch_radius>
                <surface_radius>0</surface_radius>
                <use_patch_radius>1</use_patch_radius>
                <ode>
                  <slip>0</slip>
                </ode>
              </torsional>
            </friction>
            <bounce>
              <restitution_coefficient>0</restitution_coefficient>
              <threshold>1e+06</threshold>
            </bounce>
            <contact>
              <collide_without_contact>0</collide_without_contact>
              <collide_without_contact_bitmask>1</collide_without_contact_bitmask>
              <collide_bitmask>65535</collide_bitmask>
              <ode>
                <soft_cfm>0</soft_cfm>
                <soft_erp>0</soft_erp>
                <kp>1e+13</kp>
                <kd>0</kd>
                <max_vel>0.1</max_vel>
                <min_depth>0</min_depth>
              </ode>
              <bullet>
                <split_impulse>1</split_impulse>
                <split_impulse_penetration_threshold>-0.01</split_impulse_penetration_threshold>
                <soft_cfm>0</soft_cfm>
                <soft_erp>0</soft_erp>
                <kp>1e+13</kp>
                <kd>1</kd>
              </bullet>
            </contact>
          </surface>
          <max_contacts>10000</max_contacts>
        </collision>
        <visual name='visual'>
          <cast_shadows>0</cast_shadows>
          <geometry>
            <plane>
              <normal>0 0 1</normal>
              <size>100 100</size>
            </plane>
          </geometry>
          <material>
            <script>
              <uri>file://media/materials/scripts/gazebo.material</uri>
              <name>Gazebo/Grey</name>
            </script>
          </material>
        </visual>
        <enable_wind>0</enable_wind>
        <kinematic>0</kinematic>
        <self_collide>0</self_collide>
      </link>
    </model>

    <light name='sun' type='directional'>
      <cast_shadows>1</cast_shadows>
      <pose>0 0 10 0 -0 0</pose>
      <diffuse>0.8 0.8 0.8 1</diffuse>
      <specular>0.2 0.2 0.2 1</specular>
      <attenuation>
        <range>1000</range>
        <constant>0.9</constant>
        <linear>0.01</linear>
        <quadratic>0.001</quadratic>
      </attenuation>
      <direction>-0.5 0.1 -0.9</direction>
      <spot>
        <inner_angle>0</inner_angle>
        <outer_angle>0</outer_angle>
        <falloff>0</falloff>
      </spot>
    </light>

    <gravity>0 0 -9.8</gravity>
    <magnetic_field>6e-06 2.3e-05 -4.2e-05</magnetic_field>
    <atmosphere type='adiabatic'/>
    <physics type='ode'>
      <max_step_size>0.001</max_step_size>
      <real_time_factor>1</real_time_factor>
      <real_time_update_rate>1000</real_time_update_rate>
    </physics>
    <scene>
      <ambient>0.4 0.4 0.4 1</ambient>
      <background>0.7 0.7 0.7 1</background>
      <shadows>1</shadows>
    </scene>
    <wind/>
    <spherical_coordinates>
      <surface_model>EARTH_WGS84</surface_model>
      <latitude_deg>0</latitude_deg>
      <longitude_deg>0</longitude_deg>
      <elevation>0</elevation>
      <heading_deg>0</heading_deg>
    </spherical_coordinates>

    <state world_name='default'>
      <sim_time>0 0</sim_time>
      <real_time>0 0</real_time>
      <wall_time>1720514551 614704389</wall_time>
      <iterations>0</iterations>

      <model name='ground_plane'>
        <pose>0 0 0 0 -0 0</pose>
        <scale>1 1 1</scale>
        <link name='link'>
          <pose>0 0 0 0 -0 0</pose>
          <velocity>0 0 0 0 -0 0</velocity>
          <acceleration>0 0 0 0 -0 0</acceleration>
          <wrench>0 0 0 0 -0 0</wrench>
        </link>
      </model>

      <light name='sun'>
        <pose>0 0 10 0 -0 0</pose>
      </light>
    </state>

    <gui fullscreen='0'>
      <camera name='user_camera'>
        <pose>2.65863 -0.097015 0.471525 0 0.435646 3.09138</pose>
        <view_controller>orbit</view_controller>
        <projection_type>perspective</projection_type>
      </camera>
    </gui>

    <model name='chair'>
      <pose>1.0 2.0 -0.005 0 0 0</pose>
      <link name='body'>   
        <self_collide>0</self_collide>
        <enable_wind>0</enable_wind>
        <kinematic>1</kinematic>
        <gravity>1</gravity>
        <inertial>
          <mass>1</mass>
          <pose>0 0 0 0 -0 0</pose>
          <inertia>
            <ixx>1</ixx>
            <ixy>0</ixy>
            <ixz>0</ixz>
            <iyy>1</iyy>
            <iyz>0</iyz>
            <izz>1</izz>
          </inertia>
        </inertial>
        <collision name='collision'>
          <geometry>
            <mesh>
              <uri>file:///home/jeong/gazebo_simulation/src/cleaner_simulation/cadfile/new_chair1.stl</uri>
              <scale>0.001 0.001 0.001</scale>
            </mesh>
          </geometry>
          <max_contacts>100</max_contacts>
          <surface>
            <friction>
              <ode>
                <mu>0.6</mu>
                <mu2>0.6</mu2>
                <fdir1>0 0 0</fdir1>
                <slip1>0.02</slip1>
                <slip2>0.02</slip2>
              </ode>
              <torsional>
                <coefficient>1</coefficient>
                <patch_radius>0</patch_radius>
                <surface_radius>0</surface_radius>
                <use_patch_radius>1</use_patch_radius>
                <ode>
                  <slip>0</slip>
                </ode>
              </torsional>
            </friction>
            <bounce>
              <restitution_coefficient>0</restitution_coefficient>
              <threshold>1e+06</threshold>
            </bounce>
            <contact>
              <collide_without_contact>0</collide_without_contact>
              <collide_without_contact_bitmask>1</collide_without_contact_bitmask>
              <collide_bitmask>65535</collide_bitmask>
              <ode>
                <soft_cfm>0</soft_cfm>
                <soft_erp>0</soft_erp>
                <kp>1e+13</kp>
                <kd>1</kd>
                <max_vel>2</max_vel>
                <min_depth>0</min_depth>
              </ode>
              <bullet>
                <split_impulse>1</split_impulse>
                <split_impulse_penetration_threshold>-0.01</split_impulse_penetration_threshold>
                <soft_cfm>0</soft_cfm>
                <soft_erp>0</soft_erp>
                <kp>1e+13</kp>
                <kd>1</kd>
              </bullet>
            </contact>
          </surface>
        </collision>
        <visual name='visual'>
          <geometry>
            <mesh>
              <uri>file:///home/jeong/gazebo_simulation/src/cleaner_simulation/cadfile/new_chair1.stl</uri>
              <scale>0.001 0.001 0.001</scale>
            </mesh>
          </geometry>
          <material>
            <shader type='pixel'>
              <normal_map>__default__</normal_map>
            </shader>
            <script>
              <name>ModelPreview_1::body::visual_MATERIAL_</name>
              <uri>__default__</uri>
            </script>
            <ambient>0 0 0 1</ambient>
            <diffuse>0 0 0 1</diffuse>
            <specular>0 0 0 1</specular>
            <emissive>0 0 0 1</emissive>
          </material>
          <pose>0 0 0 0 -0 0</pose>
          <transparency>0</transparency>
          <cast_shadows>1</cast_shadows>
        </visual>
      </link>
      <static>1</static>
      <allow_auto_disable>1</allow_auto_disable>
      <pose>0 0 0 0 -0 0</pose>
    </model>

    <model name='chair_frame1'>
        <!-- <pose>1.20087 0 0.013622 1.57079632679 -0 0</pose> -->
      <pose>1.0 -2 -0.005 0 -0 0</pose>
      <link name='body'>
        <self_collide>0</self_collide>
        <enable_wind>0</enable_wind>
        <kinematic>1</kinematic>
        <pose>0 0 0 0 -0 0</pose>
        <gravity>1</gravity>
        <inertial>
          <mass>1</mass>
          <pose>0 0 0 0 -0 0</pose>
          <inertia>
            <ixx>1</ixx>
            <ixy>0</ixy>
            <ixz>0</ixz>
            <iyy>1</iyy>
            <iyz>0</iyz>
            <izz>1</izz>
          </inertia>
        </inertial>
        <collision name='collision'>
          <geometry>
            <mesh>
              <!-- <uri>file:///home/jeong/gazebo_simulation/src/cleaner_simulation/cadfile/chair_frame.stl</uri> -->
              <uri>file:///home/jeong/gazebo_simulation/src/cleaner_simulation/cadfile/new_chair2.stl</uri>
              <scale>0.001 0.001 0.001</scale>
            </mesh>
          </geometry>
          <max_contacts>10</max_contacts>
          <surface>
            <contact>
              <ode/>
            </contact>
            <bounce/>
            <friction>
              <torsional>
                <ode/>
              </torsional>
              <ode/>
            </friction>
          </surface>
        </collision>
        <visual name='visual'>
          <geometry>
            <mesh>
              <uri>file:///home/jeong/gazebo_simulation/src/cleaner_simulation/cadfile/new_chair2.stl</uri>
              <scale>0.001 0.001 0.001</scale>
            </mesh>
          </geometry>
          <material>
            <shader type='pixel'>
              <normal_map>__default__</normal_map>
            </shader>
            <script>
              <name>ModelPreview_1::body::visual_MATERIAL_</name>
              <uri>__default__</uri>
            </script>
            <ambient>0 0 0 1</ambient>
            <diffuse>0 0 0 1</diffuse>
            <specular>0 0 0 1</specular>
            <emissive>0 0 0 1</emissive>
          </material>
          <pose>0 0 0 0 -0 0</pose>
          <transparency>0</transparency>
          <cast_shadows>1</cast_shadows>
        </visual>
      </link>
      <static>1</static>
      <allow_auto_disable>1</allow_auto_disable>

    </model>

    <model name='hanger1'>
      <pose>1.4 0.18 0.00 0 -0 0</pose>
      <link name='body'>
        <self_collide>0</self_collide>
        <enable_wind>0</enable_wind>
        <kinematic>1</kinematic>
        <pose>0 0 0 0 -0 0</pose>
        <gravity>1</gravity>
        <inertial>
          <mass>1</mass>
          <pose>0 0 0 0 -0 0</pose>
          <inertia>
            <ixx>1</ixx>
            <ixy>0</ixy>
            <ixz>0</ixz>
            <iyy>1</iyy>
            <iyz>0</iyz>
            <izz>1</izz>
          </inertia>
        </inertial>
        <collision name='collision'>
          <geometry>
            <mesh>
              <uri>file:///home/jeong/gazebo_simulation/src/cleaner_simulation/cadfile/hanger10.stl</uri>
              <scale>0.001 0.001 0.001</scale>
            </mesh>
          </geometry>
          <max_contacts>10</max_contacts>
          <surface>
            <contact>
              <ode/>
            </contact>
            <bounce/>
            <friction>
             <ode>
                <mu>0.2</mu>
                <mu2>0.2</mu2>
                <fdir1>0 0 0</fdir1>
                <slip1>0.08</slip1>
                <slip2>0.08</slip2>
              </ode>
            </friction>
          </surface>
        </collision>
        <visual name='visual'>
          <geometry>
            <mesh>
              <uri>file:///home/jeong/gazebo_simulation/src/cleaner_simulation/cadfile/hanger10.stl</uri>
              <scale>0.001 0.001 0.001</scale>
            </mesh>
          </geometry>
          <material>
            <shader type='pixel'>
              <normal_map>__default__</normal_map>
            </shader>
            <script>
              <name>ModelPreview_1::body::visual_MATERIAL_</name>
              <uri>__default__</uri>
            </script>
            <ambient>0 0 0 1</ambient>
            <diffuse>0 0 0 1</diffuse>
            <specular>0 0 0 1</specular>
            <emissive>0 0 0 1</emissive>
          </material>
          <pose>0 0 0 0 -0 0</pose>
          <transparency>0</transparency>
          <cast_shadows>1</cast_shadows>
        </visual>
      </link>
      <static>1</static>
      <allow_auto_disable>1</allow_auto_disable>
    </model>

    <model name='hanger2'>
      <pose>0.35 1.0 0.00 0 -0 0</pose>
      <link name='body'>
        <self_collide>0</self_collide>
        <enable_wind>0</enable_wind>
        <kinematic>1</kinematic>
        <pose>0 0 0 0 -0 0</pose>
        <gravity>1</gravity>
        <inertial>
          <mass>1</mass>
          <pose>0 0 0 0 -0 0</pose>
          <inertia>
            <ixx>1</ixx>
            <ixy>0</ixy>
            <ixz>0</ixz>
            <iyy>1</iyy>
            <iyz>0</iyz>
            <izz>1</izz>
          </inertia>
        </inertial>
        <collision name='collision'>
          <geometry>
            <mesh>
              <uri>file:///home/jeong/gazebo_simulation/src/cleaner_simulation/cadfile/hanger15.stl</uri>
              <scale>0.001 0.001 0.001</scale>
            </mesh>
          </geometry>
          <max_contacts>10</max_contacts>
          <surface>
            <contact>
              <ode/>
            </contact>
            <bounce/>
            <friction>
             <ode>
                <mu>0.2</mu>
                <mu2>0.2</mu2>
                <fdir1>0 0 0</fdir1>
                <slip1>0.08</slip1>
                <slip2>0.08</slip2>
              </ode>
            </friction>
          </surface>
        </collision>
        <visual name='visual'>
          <geometry>
            <mesh>
              <uri>file:///home/jeong/gazebo_simulation/src/cleaner_simulation/cadfile/hanger15.stl</uri>
              <scale>0.001 0.001 0.001</scale>
            </mesh>
          </geometry>
          <material>
            <shader type='pixel'>
              <normal_map>__default__</normal_map>
            </shader>
            <script>
              <name>ModelPreview_1::body::visual_MATERIAL_</name>
              <uri>__default__</uri>
            </script>
            <ambient>0 0 0 1</ambient>
            <diffuse>0 0 0 1</diffuse>
            <specular>0 0 0 1</specular>
            <emissive>0 0 0 1</emissive>
          </material>
          <pose>0 0 0 0 -0 0</pose>
          <transparency>0</transparency>
          <cast_shadows>1</cast_shadows>
        </visual>
      </link>
      <static>1</static>
      <allow_auto_disable>1</allow_auto_disable>
    </model>

    <model name='plate1'>
      <pose>0.35 0.15 -0.02 0 -0 0</pose>
      <link name='body'>
        <self_collide>0</self_collide>
        <enable_wind>0</enable_wind>
        <kinematic>1</kinematic>
        <pose>0 0 0 0 -0 0</pose>
        <gravity>1</gravity>
        <inertial>
          <mass>1</mass>
          <pose>0 0 0 0 -0 0</pose>
          <inertia>
            <ixx>1</ixx>
            <ixy>0</ixy>
            <ixz>0</ixz>
            <iyy>1</iyy>
            <iyz>0</iyz>
            <izz>1</izz>
          </inertia>
        </inertial>
        <collision name='collision'>
          <geometry>
            <mesh>
              <uri>file:///home/jeong/gazebo_simulation/src/cleaner_simulation/cadfile/plate50.stl</uri>
              <scale>0.001 0.001 0.001</scale>
            </mesh>
          </geometry>
          <max_contacts>10</max_contacts>
          <surface>
            <contact>
              <ode/>
            </contact>
            <bounce/>
            <friction>
             <ode>
                <mu>0.2</mu>
                <mu2>0.2</mu2>
                <fdir1>0 0 0</fdir1>
                <slip1>0.08</slip1>
                <slip2>0.08</slip2>
              </ode>
            </friction>
          </surface>
        </collision>
        <visual name='visual'>
          <geometry>
            <mesh>
              <uri>file:///home/jeong/gazebo_simulation/src/cleaner_simulation/cadfile/plate50.stl</uri>
              <scale>0.001 0.001 0.001</scale>
            </mesh>
          </geometry>
          <material>
            <shader type='pixel'>
              <normal_map>__default__</normal_map>
            </shader>
            <script>
              <name>ModelPreview_1::body::visual_MATERIAL_</name>
              <uri>__default__</uri>
            </script>
            <ambient>0 0 0 1</ambient>
            <diffuse>0 0 0 1</diffuse>
            <specular>0 0 0 1</specular>
            <emissive>0 0 0 1</emissive>
          </material>
          <pose>0 0 0 0 -0 0</pose>
          <transparency>0</transparency>
          <cast_shadows>1</cast_shadows>
        </visual>
      </link>
      <static>1</static>
      <allow_auto_disable>1</allow_auto_disable>
    </model>

    <model name='scales'>
      <pose>1.5 0.0 0.016 1.57079632679 -0 0</pose>
      <link name='body'>
        <self_collide>0</self_collide>
        <enable_wind>0</enable_wind>
        <kinematic>1</kinematic>
        <pose>0 0 0 0 -0 0</pose>
        <gravity>1</gravity>
        <inertial>
          <mass>1</mass>
          <pose>0 0 0 0 -0 0</pose>
          <inertia>
            <ixx>1</ixx>
            <ixy>0</ixy>
            <ixz>0</ixz>
            <iyy>1</iyy>
            <iyz>0</iyz>
            <izz>1</izz>
          </inertia>
        </inertial>
        <collision name='collision'>
          <geometry>
            <mesh>
              <uri>file:///home/jeong/gazebo_simulation/src/cleaner_simulation/cadfile/scales.stl</uri>
              <scale>0.001 0.001 0.001</scale>
            </mesh>
          </geometry>
          <max_contacts>100</max_contacts>
          <surface>
            <contact>
              <ode/>
            </contact>
            <bounce/>
            <friction>
              <torsional>
                <ode/>
              </torsional>
              <ode/>
            </friction>
          </surface>
        </collision>
        <visual name='visual'>
          <geometry>
            <mesh>
              <uri>file:///home/jeong/gazebo_simulation/src/cleaner_simulation/cadfile/scales.stl</uri>
              <scale>0.001 0.001 0.001</scale>
            </mesh>
          </geometry>
          <material>
            <shader type='pixel'>
              <normal_map>__default__</normal_map>
            </shader>
            <script>
              <name>ModelPreview_1::body::visual_MATERIAL_</name>
              <uri>__default__</uri>
            </script>
            <ambient>0 0 0 1</ambient>
            <diffuse>0 0 0 1</diffuse>
            <specular>0 0 0 1</specular>
            <emissive>0 0 0 1</emissive>
          </material>
          <pose>0 0 0 0 -0 0</pose>
          <transparency>0</transparency>
          <cast_shadows>1</cast_shadows>
        </visual>
      </link>
      <static>1</static>
      <allow_auto_disable>1</allow_auto_disable>

    </model>

    <model name='door_frame'>
      <pose>0.5 3.0 -0.01 0 0 0</pose>
      <link name='body'>
        <self_collide>0</self_collide>
        <enable_wind>0</enable_wind>
        <kinematic>0</kinematic>
        <pose>0 -0 0 0 -0 0</pose>
        <gravity>1</gravity>
        <inertial>
          <mass>1</mass>
          <pose>0 0 0 0 -0 0</pose>
          <inertia>
            <ixx>1</ixx>
            <ixy>0</ixy>
            <ixz>0</ixz>
            <iyy>1</iyy>
            <iyz>0</iyz>
            <izz>1</izz>
          </inertia>
        </inertial>
        <visual name='visual'>
          <geometry>
            <mesh>
              <uri>file:///home/jeong/gazebo_simulation/src/cleaner_simulation/cadfile/new_door.stl</uri>
              <scale>0.001 0.001 0.001</scale>
            </mesh>
          </geometry>
          <material>
            <shader type='pixel'>
              <normal_map>__default__</normal_map>
            </shader>
            <script>
              <name>ModelPreview_1::body::visual_MATERIAL_</name>
              <uri>__default__</uri>
            </script>
            <ambient>0 0 0 1</ambient>
            <diffuse>0 0 0 1</diffuse>
            <specular>0 0 0 1</specular>
            <emissive>0 0 0 1</emissive>
          </material>
          <pose>0 0 0 0 -0 0</pose>
          <transparency>0</transparency>
          <cast_shadows>1</cast_shadows>
        </visual>
        <collision name='collision'>
          <laser_retro>0</laser_retro>
          <max_contacts>200</max_contacts>
          <pose>0 0 0 0 -0 0</pose>
          <geometry>
            <mesh>
              <uri>file:///home/jeong/gazebo_simulation/src/cleaner_simulation/cadfile/new_door.stl</uri>
              <scale>0.001 0.001 0.001</scale>
            </mesh>
          </geometry>
          <surface>
            <friction>
              <ode>
                <mu>0.8</mu>
                <mu2>0.8</mu2>
                <fdir1>0 0 0</fdir1>
                <slip1>0.02</slip1>
                <slip2>0.02</slip2>
              </ode>
              <torsional>
                <coefficient>1</coefficient>
                <patch_radius>0</patch_radius>
                <surface_radius>0</surface_radius>
                <use_patch_radius>1</use_patch_radius>
                <ode>
                  <slip>0</slip>
                </ode>
              </torsional>
            </friction>
            <bounce>
              <restitution_coefficient>0.15</restitution_coefficient>
              <threshold>0.05</threshold>
            </bounce>
            <contact>
              <collide_without_contact>0</collide_without_contact>
              <collide_without_contact_bitmask>1</collide_without_contact_bitmask>
              <collide_bitmask>65535</collide_bitmask>
              <ode>
                <soft_cfm>0</soft_cfm>
                <soft_erp>0</soft_erp>
                <kp>1e+13</kp>
                <kd>1</kd>
                <max_vel>0.01</max_vel>
                <min_depth>0</min_depth>
              </ode>
              <bullet>
                <split_impulse>1</split_impulse>
                <split_impulse_penetration_threshold>-0.01</split_impulse_penetration_threshold>
                <soft_cfm>0</soft_cfm>
                <soft_erp>0</soft_erp>
                <kp>1e+13</kp>
                <kd>1</kd>
              </bullet>
            </contact>
          </surface>
        </collision>
      </link>
      <static>1</static>
      <allow_auto_disable>1</allow_auto_disable>
    </model>

    <model name='robot_cleaner'>
      <plugin name='cleaner' filename='libmodel_control_plugin.so'>
        <wheel_p_gain>0.9</wheel_p_gain>
        <wheel_i_gain>0.007</wheel_i_gain>
        <wheel_d_gain>0.0</wheel_d_gain>
        <motor_updateRateHZ>1000.00</motor_updateRateHZ>
      </plugin>
      <static>0</static>
      <link name='chassis'>
        <self_collide>0</self_collide>
        <pose>0 0 0.018 0 -0 0</pose>
        <inertial>
          <pose>0.0 0 0.054838554 0 -0 0</pose>
          <mass>4</mass>
          <inertia>
            <ixx>2.7118881e-02</ixx>
            <iyy>2.8366524e-02</iyy>
            <izz>4.4452848e-02</izz>
            <ixy>0</ixy>
            <ixz>2.6988632e-03</ixz>
            <iyz>0</iyz>
          </inertia>
        </inertial>
        <collision name='collision'>
          <geometry>
            <mesh>
              <uri>file:///home/jeong/gazebo_simulation/src/cleaner_simulation/cadfile/chassis.stl</uri>
              <scale>0.001 0.001 0.001</scale>
            </mesh>
          </geometry>
          <max_contacts>20</max_contacts>
          <surface>
            <friction>
              <ode>
                <mu>0.35</mu>
                <mu2>0.35</mu2>
                <fdir1>0 0 0</fdir1>
                <slip1>0.05</slip1>
                <slip2>0.05</slip2>
              </ode>
              <torsional>
                <coefficient>1</coefficient>
                <patch_radius>0</patch_radius>
                <surface_radius>0</surface_radius>
                <use_patch_radius>1</use_patch_radius>
                <ode>
                  <slip>0</slip>
                </ode>
              </torsional>
            </friction>
            <bounce>
              <restitution_coefficient>0.15</restitution_coefficient>
              <threshold>0.005</threshold>
            </bounce>
            <contact>
              <collide_without_contact>0</collide_without_contact>
              <collide_without_contact_bitmask>1</collide_without_contact_bitmask>
              <collide_bitmask>65535</collide_bitmask>
              <ode>
                <soft_cfm>0</soft_cfm>
                <soft_erp>0</soft_erp>
                <kp>1e+13</kp>
                <kd>1</kd>
                <max_vel>2</max_vel>
                <min_depth>0</min_depth>
              </ode>
              <bullet>
                <split_impulse>1</split_impulse>
                <split_impulse_penetration_threshold>-0.01</split_impulse_penetration_threshold>
                <soft_cfm>0</soft_cfm>
                <soft_erp>0</soft_erp>
                <kp>1e+13</kp>
                <kd>1</kd>
              </bullet>
            </contact>
          </surface>
        </collision>

        <visual name='visual'>
          <geometry>
            <mesh>
              <uri>file:///home/jeong/gazebo_simulation/src/cleaner_simulation/cadfile/chassis.stl</uri>
              <scale>0.001 0.001 0.001</scale>
            </mesh>
          </geometry>
          <material>
            <script>
              <uri>file://media/materials/scripts/gazebo.material</uri>
              <name>Gazebo/Grey</name>
            </script>
          </material>
        </visual>
        <visual name='sensor_visual'>
          <pose>0 0 0.11 0 -0 0</pose>
          <geometry>
            <mesh>
              <uri>model://hokuyo/meshes/hokuyo.dae</uri>
            </mesh>
          </geometry>
        </visual>
        <sensor name='laser' type='ray'>
          <pose>0 0 0.135 0 -0 0</pose>
          <ray>
            <scan>
              <horizontal>
                <samples>360</samples>
                <resolution>1</resolution>
                <min_angle>-3.14159</min_angle>
                <max_angle>3.14159</max_angle>
              </horizontal>
              <vertical>
                <samples>1</samples>
                <min_angle>0</min_angle>
                <max_angle>0</max_angle>
              </vertical>
            </scan>
            <range>
              <min>0.33</min>
              <max>3.5</max>
              <resolution>0.01</resolution>
            </range>
            <noise>
              <type>gaussian</type>
              <mean>0</mean>
              <stddev>0.01</stddev>
            </noise>
          </ray>
          <plugin name='gazebo_ros_laser_controller' filename='libgazebo_ros_laser.so'>
            <topicName>/robot_cleaner/laser</topicName>
            <frameName>chassis_frame</frameName>
            <updateRateHZ>1.0</updateRateHZ>
          </plugin>
          <always_on>1</always_on>
          <visualize>0</visualize>
        </sensor>
        <sensor name='imu_sensor' type='imu'>
          <imu>
            <angular_velocity>
              <x>
                <noise type='gaussian'>
                  <mean>0</mean>
                  <stddev>0.0002</stddev>
                  <bias_mean>7.5e-06</bias_mean>
                  <bias_stddev>8e-07</bias_stddev>
                </noise>
              </x>
              <y>
                <noise type='gaussian'>
                  <mean>0</mean>
                  <stddev>0.0002</stddev>
                  <bias_mean>7.5e-06</bias_mean>
                  <bias_stddev>8e-07</bias_stddev>
                </noise>
              </y>
              <z>
                <noise type='gaussian'>
                  <mean>0</mean>
                  <stddev>0.0002</stddev>
                  <bias_mean>7.5e-06</bias_mean>
                  <bias_stddev>8e-07</bias_stddev>
                </noise>
              </z>
            </angular_velocity>
            <linear_acceleration>
              <x>
                <noise type='gaussian'>
                  <mean>0</mean>
                  <stddev>0.017</stddev>
                  <bias_mean>0.0</bias_mean>
                  <bias_stddev>0.001</bias_stddev>
                </noise>
              </x>
              <y>
                <noise type='gaussian'>
                  <mean>0</mean>
                  <stddev>0.017</stddev>
                  <bias_mean>0.0</bias_mean>
                  <bias_stddev>0.001</bias_stddev>
                </noise>
              </y>
              <z>
                <noise type='gaussian'>
                  <mean>0</mean>
                  <stddev>0.017</stddev>
                  <bias_mean>0.0</bias_mean>
                  <bias_stddev>0.001</bias_stddev>
                </noise>
              </z>
            </linear_acceleration>
          </imu>
          <plugin name='gazebo_ros_imu' filename='libgazebo_ros_imu_sensor.so'>
            <topicName>/robot_cleaner/imu</topicName>
            <frameName>chassis_link</frameName>
            <updateRateHZ>200.0</updateRateHZ>
            <initialOrientationAsReference>0</initialOrientationAsReference>
          </plugin>
          <always_on>1</always_on>
        </sensor>
        <enable_wind>0</enable_wind>
        <kinematic>0</kinematic>
      </link>


      <link name='caster'>
        <pose>-0.065 0.0 0.018 0 -0 0</pose>
        <inertial>
          <pose>-3.2585968e-03  0.0000000e+00 -5.5926975e-03 0 -0 0</pose>
          <mass>0.03</mass>
          <inertia>
            <ixx>1.9500992e-06</ixx>
            <iyy>2.1103043e-06</iyy>
            <izz>3.1099810e-06</izz>
            <ixy>0</ixy>
            <ixz>-2.7616595e-07</ixz>
            <iyz>0</iyz>
          </inertia>
        </inertial>
        <collision name='collision'>
          <geometry>
            <mesh>
              <uri>file:///home/jeong/gazebo_simulation/src/cleaner_simulation/cadfile/caster.stl</uri>
              <scale>1 1 1</scale>
            </mesh>
          </geometry>
          <max_contacts>10</max_contacts>
          <surface>
            <friction>
              <ode>
                <mu>0.2</mu>
                <mu2>0.2</mu2>
                <fdir1>0 0 0</fdir1>
                <slip1>0.01</slip1>
                <slip2>0.01</slip2>
              </ode>
              <torsional>
                <coefficient>1</coefficient>
                <patch_radius>0</patch_radius>
                <surface_radius>0</surface_radius>
                <use_patch_radius>1</use_patch_radius>
                <ode>
                  <slip>0</slip>
                </ode>
              </torsional>
            </friction>
            <contact>
              <collide_without_contact>0</collide_without_contact>
              <collide_without_contact_bitmask>1</collide_without_contact_bitmask>
              <collide_bitmask>65535</collide_bitmask>
              <ode>
                <soft_cfm>0</soft_cfm>
                <soft_erp>0</soft_erp>
                <kp>1e+13</kp>
                <kd>1</kd>
                <max_vel>1</max_vel>
                <min_depth>0</min_depth>
              </ode>
              <bullet>
                <split_impulse>1</split_impulse>
                <split_impulse_penetration_threshold>-0.01</split_impulse_penetration_threshold>
                <soft_cfm>0</soft_cfm>
                <soft_erp>0</soft_erp>
                <kp>1e+13</kp>
                <kd>1</kd>
              </bullet>
            </contact>
          </surface>
        </collision>
        <visual name='visual'>
          <geometry>
            <mesh>
              <uri>file:///home/jeong/gazebo_simulation/src/cleaner_simulation/cadfile/caster.stl</uri>
              <scale>1 1 1</scale>
            </mesh>
          </geometry>
        </visual>
        <enable_wind>0</enable_wind>
        <self_collide>0</self_collide>
        <kinematic>0</kinematic>
      </link>
      <joint name='caster_spin' type='revolute'>
        <parent>chassis</parent>
        <child>caster</child>
        <axis>
          <xyz>0 0 1</xyz>
          <limit>
            <lower>-1e+16</lower>
            <upper>1e+16</upper>
          </limit>
          <dynamics>
            <friction>0.004</friction>
            <spring_reference>0</spring_reference>
            <spring_stiffness>0</spring_stiffness>
          </dynamics>
        </axis>
      </joint>

      <link name='wheel_caster'>
        <pose>-0.07375 0.0 0.007 -1.57079632679 -0 0</pose>
        <inertial>
          <pose>0 0 0 0 -0 0</pose>
          <mass>0.01</mass>
          <inertia>
            <ixx>1.5250000000000002e-07</ixx>
            <iyy>1.5250000000000002e-07</iyy>
            <izz>2.4500000000000004e-07</izz>
            <ixy>0</ixy>
            <ixz>0</ixz>
            <iyz>0</iyz>
          </inertia>
        </inertial>
        <collision name='collision'>
          <geometry>
            <cylinder>
              <radius>0.007</radius>
              <length>0.006</length>
            </cylinder>
          </geometry>
          <max_contacts>10</max_contacts>
          <surface>
            <friction>
              <ode>
                <mu>1.0</mu>
                <mu2>1.0</mu2>
                <fdir1>0 0 0</fdir1>
                <slip1>0.00</slip1>
                <slip2>0.00</slip2>
              </ode>
              <torsional>
                <coefficient>1</coefficient>
                <patch_radius>0</patch_radius>
                <surface_radius>0</surface_radius>
                <use_patch_radius>1</use_patch_radius>
                <ode>
                  <slip>0</slip>
                </ode>
              </torsional>
            </friction>

            <contact>
              <collide_without_contact>0</collide_without_contact>
              <collide_without_contact_bitmask>1</collide_without_contact_bitmask>
              <collide_bitmask>65535</collide_bitmask>
              <ode>
                <soft_cfm>0</soft_cfm>
                <soft_erp>0</soft_erp>
                <kp>1e+13</kp>
                <kd>1</kd>
                <max_vel>1</max_vel>
                <min_depth>0</min_depth>
              </ode>
              <bullet>
                <split_impulse>1</split_impulse>
                <split_impulse_penetration_threshold>-0.01</split_impulse_penetration_threshold>
                <soft_cfm>0</soft_cfm>
                <soft_erp>0</soft_erp>
                <kp>1e+13</kp>
                <kd>1</kd>
              </bullet>
            </contact>
          </surface>
        </collision>
        <visual name='visual'>
          <geometry>
            <cylinder>
              <radius>0.007</radius>
              <length>0.006</length>
            </cylinder>

          </geometry>
          <material>
            <script>
              <uri>file://media/materials/scripts/gazebo.material</uri>
              <name>Gazebo/Black</name>
            </script>
          </material>
        </visual>

        <enable_wind>0</enable_wind>
        <self_collide>0</self_collide>
        <kinematic>0</kinematic>
      </link>

      <joint name='wheel_caster_spin' type='revolute'>
        <parent>caster</parent>
        <child>wheel_caster</child>
        <axis>
          <xyz>0 0 1</xyz>
          <limit>
            <lower>-1e+16</lower>
            <upper>1e+16</upper>
          </limit>
          <dynamics>
            <spring_reference>0</spring_reference>
            <spring_stiffness>0</spring_stiffness>
          </dynamics>
        </axis>
        
      </joint>


      <link name='wheel_front_left'>
        <pose>0.065 0.111 0.01 -1.57079632679 -0 0</pose>
        <inertial>
          <mass>0.01</mass>
          <inertia>
            <ixx>2.8e-07</ixx>
            <iyy>2.8e-07</iyy>
            <izz>5.000000000000001e-07</izz>
            <ixy>0</ixy>
            <ixz>0</ixz>
            <iyz>0</iyz>
          </inertia>
          <pose>0 0 0 0 -0 0</pose>
        </inertial>
        <collision name='collision'>
          <geometry>
            <cylinder>
              <radius>0.01</radius>
              <length>0.006</length>
            </cylinder>
          </geometry>
          <max_contacts>10</max_contacts>
          <surface>
            <friction>
              <ode>
                <mu>1.0</mu>
                <mu2>1.0</mu2>
                <fdir1>0 0 0</fdir1>
                <slip1>0.00</slip1>
                <slip2>0.00</slip2>
              </ode>
              <torsional>
                <coefficient>1</coefficient>
                <patch_radius>0</patch_radius>
                <surface_radius>0</surface_radius>
                <use_patch_radius>1</use_patch_radius>
                <ode>
                  <slip>0</slip>
                </ode>
              </torsional>
            </friction>

            <contact>
              <collide_without_contact>0</collide_without_contact>
              <collide_without_contact_bitmask>1</collide_without_contact_bitmask>
              <collide_bitmask>65535</collide_bitmask>
              <ode>
                <soft_cfm>0</soft_cfm>
                <soft_erp>0</soft_erp>
                <kp>1e+13</kp>
                <kd>1</kd>
                <max_vel>1</max_vel>
                <min_depth>0</min_depth>
              </ode>
              <bullet>
                <split_impulse>1</split_impulse>
                <split_impulse_penetration_threshold>-0.01</split_impulse_penetration_threshold>
                <soft_cfm>0</soft_cfm>
                <soft_erp>0</soft_erp>
                <kp>1e+13</kp>
                <kd>1</kd>
              </bullet>
            </contact>
          </surface>
        </collision>
        <visual name='visual'>
          <geometry>
            <cylinder>
              <radius>0.01</radius>
              <length>0.006</length>
            </cylinder>

          </geometry>
          <material>
            <script>
              <uri>file://media/materials/scripts/gazebo.material</uri>
              <name>Gazebo/Black</name>
            </script>
          </material>
        </visual>

        <enable_wind>0</enable_wind>
        <self_collide>0</self_collide>
        <kinematic>0</kinematic>
      </link>

      <joint name='wheel_front_left_spin' type='revolute'>
        <parent>chassis</parent>
        <child>wheel_front_left</child>
        <axis>
          <xyz>0 0 1</xyz>
          <limit>
            <lower>-1e+16</lower>
            <upper>1e+16</upper>
          </limit>
          <dynamics>
            <friction>0.004</friction>
            <spring_reference>0</spring_reference>
            <spring_stiffness>0</spring_stiffness>
          </dynamics>
        </axis>
      </joint>

      <link name='wheel_front_right'>
        <pose>0.065 -0.111 0.01 -1.57079632679 0 0</pose>
        <inertial>
          <mass>0.01</mass>
          <inertia>
            <ixx>2.8e-07</ixx>
            <iyy>2.8e-07</iyy>
            <izz>5.000000000000001e-07</izz>
            <ixy>0</ixy>
            <ixz>0</ixz>
            <iyz>0</iyz>
          </inertia>
          <pose>0 0 0 0 -0 0</pose>
        </inertial>
        <collision name='collision'>
          <geometry>
            <cylinder>
              <radius>0.01</radius>
              <length>0.006</length>
            </cylinder>

          </geometry>
          <max_contacts>10</max_contacts>
          <surface>
            <friction>
              <ode>
                <mu>1.0</mu>
                <mu2>1.0</mu2>
                <fdir1>0 0 0</fdir1>
                <slip1>0.00</slip1>
                <slip2>0.00</slip2>
              </ode>
              <torsional>
                <coefficient>1</coefficient>
                <patch_radius>0</patch_radius>
                <surface_radius>0</surface_radius>
                <use_patch_radius>1</use_patch_radius>
                <ode>
                  <slip>0</slip>
                </ode>
              </torsional>
            </friction>

            <contact>
              <collide_without_contact>0</collide_without_contact>
              <collide_without_contact_bitmask>1</collide_without_contact_bitmask>
              <collide_bitmask>65535</collide_bitmask>
              <ode>
                <soft_cfm>0</soft_cfm>
                <soft_erp>0</soft_erp>
                <kp>1e+13</kp>
                <kd>1</kd>
                <max_vel>0.1</max_vel>
                <min_depth>0</min_depth>
              </ode>
              <bullet>
                <split_impulse>1</split_impulse>
                <split_impulse_penetration_threshold>-0.01</split_impulse_penetration_threshold>
                <soft_cfm>0</soft_cfm>
                <soft_erp>0</soft_erp>
                <kp>1e+13</kp>
                <kd>1</kd>
              </bullet>
            </contact>
          </surface>
        </collision>
        <visual name='visual'>
          <geometry>
            <cylinder>
              <radius>0.01</radius>
              <length>0.006</length>
            </cylinder>
          </geometry>
          <material>
            <script>
              <uri>file://media/materials/scripts/gazebo.material</uri>
              <name>Gazebo/Black</name>
            </script>
          </material>
        </visual>

        <enable_wind>0</enable_wind>
        <self_collide>0</self_collide>
        <kinematic>0</kinematic>
      </link>

      <joint name='wheel_front_right_spin' type='revolute'>
        <parent>chassis</parent>
        <child>wheel_front_right</child>
        <axis>
          <xyz>0 0 1</xyz>
          <limit>
            <lower>-1e+16</lower>
            <upper>1e+16</upper>
          </limit>
          <dynamics>
            <friction>0.004</friction>
            <spring_reference>0</spring_reference>
            <spring_stiffness>0</spring_stiffness>
          </dynamics>
        </axis>
      </joint>

      <link name='wheel_rear_right'>
        <pose>0 -0.114 0.0375 -1.57079632679 0 0</pose>
        <inertial>
          <mass>0.046</mass>
          <inertia>
            <ixx>1.72797e-05</ixx>
            <iyy>1.72797e-05</iyy>
            <izz>3.23437e-05</izz>
            <ixy>0</ixy>
            <ixz>0</ixz>
            <iyz>0</iyz>
          </inertia>
          <pose>0 0 0 0 -0 0</pose>
        </inertial>
        <collision name='collision'>
          <geometry>
            <mesh>
              <uri>file:///home/jeong/gazebo_simulation/src/cleaner_simulation/cadfile/wheel_gear.stl</uri>
              <scale>0.002 0.002 0.001</scale>
            </mesh>
            <!-- <cylinder>
              <radius>0.0375</radius>
              <length>0.017</length>
            </cylinder> -->
          </geometry>
          <max_contacts>40</max_contacts>
          <surface>
            <friction>
              <ode>
                <mu>1</mu>
                <mu2>1</mu2>
                <fdir1>0 0 0</fdir1>
                <slip1>0</slip1>
                <slip2>0</slip2>
              </ode>
              <torsional>
                <coefficient>1</coefficient>
                <patch_radius>0</patch_radius>
                <surface_radius>0</surface_radius>
                <use_patch_radius>1</use_patch_radius>
                <ode>
                  <slip>0</slip>
                </ode>
              </torsional>
            </friction>
            <bounce>
              <restitution_coefficient>0</restitution_coefficient>
              <threshold>1e+06</threshold>
            </bounce>
            <contact>
              <collide_without_contact>0</collide_without_contact>
              <collide_without_contact_bitmask>1</collide_without_contact_bitmask>
              <collide_bitmask>65535</collide_bitmask>
              <ode>
                <soft_cfm>0</soft_cfm>
                <soft_erp>0</soft_erp>
                <kp>10000</kp>
                <kd>8</kd>
                <max_vel>10.0</max_vel>
                <min_depth>0</min_depth>
              </ode>
              <bullet>
                <split_impulse>1</split_impulse>
                <split_impulse_penetration_threshold>-0.01</split_impulse_penetration_threshold>
                <soft_cfm>0</soft_cfm>
                <soft_erp>0</soft_erp>
                <kp>1e+13</kp>
                <kd>1</kd>
              </bullet>
            </contact>
          </surface>
        </collision>
        <visual name='visual'>
          <geometry>
            <mesh>
              <uri>file:///home/jeong/gazebo_simulation/src/cleaner_simulation/cadfile/wheel_gear.stl</uri>
              <scale>0.002 0.002 0.001</scale>
            </mesh>
            <!-- <cylinder>
              <radius>0.0375</radius>
              <length>0.017</length>
            </cylinder> -->
          </geometry>
          <material>
            <script>
              <uri>file://media/materials/scripts/gazebo.material</uri>
              <name>Gazebo/Black</name>
            </script>
          </material>
        </visual>
        <enable_wind>0</enable_wind>
        <kinematic>0</kinematic>
        <self_collide>0</self_collide>

      </link>

      <link name="susp_rear_right">
        <pose>0 -0.114 0.0375  0 0 0</pose>
        <inertial>
          <mass>0.046</mass>
          <inertia>
            <ixx>7.666666666666667e-07</ixx>
            <iyy>7.666666666666667e-07</iyy>
            <izz>7.666666666666667e-07</izz>
            <ixy>0</ixy>
            <ixz>0</ixz>
            <iyz>0</iyz>
          </inertia>
        </inertial>
        <collision name="collision">
          <geometry>
            <box>
              <size>0.01 0.01 0.01</size>
            </box>
          </geometry>
        </collision>
        <visual name="visual">
          <geometry>
            <box>
              <size>0.01 0.01 0.01</size>
            </box>
          </geometry>
          <material>
            <script>
              <uri>file://media/materials/scripts/gazebo.material</uri>
              <name>Gazebo/Black</name>
            </script>
          </material>
        </visual>
      </link>

      <link name='wheel_rear_left'>
        <pose>0 0.114 0.0375 -1.57079632679 0 0</pose>
        <inertial>
          <mass>0.046</mass>
          <inertia>
            <ixx>1.72797e-05</ixx>
            <iyy>1.72797e-05</iyy>
            <izz>3.23437e-05</izz>
            <ixy>0</ixy>
            <ixz>0</ixz>
            <iyz>0</iyz>
          </inertia>
          <pose>0 0 0 0 -0 0</pose>
        </inertial>
        <collision name='collision'>
          <geometry>
            <mesh>
              <uri>file:///home/jeong/gazebo_simulation/src/cleaner_simulation/cadfile/wheel_gear.stl</uri>
              <scale>0.002 0.002 0.001</scale>
            </mesh>
            <!-- <cylinder>
              <radius>0.0375</radius>
              <length>0.017</length>
            </cylinder> -->
          </geometry>
          <max_contacts>40</max_contacts>
          <surface>
            <friction>
              <ode>
                <mu>1</mu>
                <mu2>1</mu2>
                <fdir1>0 0 0</fdir1>
                <slip1>0</slip1>
                <slip2>0</slip2>
              </ode>
              <torsional>
                <coefficient>1</coefficient>
                <patch_radius>0</patch_radius>
                <surface_radius>0</surface_radius>
                <use_patch_radius>1</use_patch_radius>
                <ode>
                  <slip>0</slip>
                </ode>
              </torsional>
            </friction>
            <bounce>
              <restitution_coefficient>0</restitution_coefficient>
              <threshold>1e+06</threshold>
            </bounce>
            <contact>
              <collide_without_contact>0</collide_without_contact>
              <collide_without_contact_bitmask>1</collide_without_contact_bitmask>
              <collide_bitmask>65535</collide_bitmask>
              <ode>
                <soft_cfm>0</soft_cfm>
                <soft_erp>0</soft_erp>
                <kp>10000</kp>
                <kd>8</kd>
                <max_vel>10.0</max_vel>
                <min_depth>0.00</min_depth>
              </ode>
              <bullet>
                <split_impulse>1</split_impulse>
                <split_impulse_penetration_threshold>-0.01</split_impulse_penetration_threshold>
                <soft_cfm>0</soft_cfm>
                <soft_erp>0</soft_erp>
                <kp>1e+13</kp>
                <kd>1</kd>
              </bullet>
            </contact>
          </surface>
        </collision>
        <visual name='visual'>
          <geometry>
            <mesh>
              <uri>file:///home/jeong/gazebo_simulation/src/cleaner_simulation/cadfile/wheel_gear.stl</uri>
              <scale>0.002 0.002 0.001</scale>
            </mesh>
            <!-- <cylinder>
              <radius>0.0375</radius>
              <length>0.017</length>
            </cylinder> -->
          </geometry>
          <material>
            <script>
              <uri>file://media/materials/scripts/gazebo.material</uri>
              <name>Gazebo/Black</name>
            </script>
          </material>
        </visual>
        <enable_wind>0</enable_wind>
        <kinematic>0</kinematic>
        <self_collide>0</self_collide>
      </link>

      <link name="susp_rear_left">
        <pose>0 0.114 0.0375  0 0 0</pose>
        <inertial>
          <mass>0.046</mass>
          <inertia>
            <ixx>7.666666666666667e-07</ixx>
            <iyy>7.666666666666667e-07</iyy>
            <izz>7.666666666666667e-07</izz>
            <ixy>0</ixy>
            <ixz>0</ixz>
            <iyz>0</iyz>
          </inertia>
        </inertial>
        <collision name="collision">
          <geometry>
            <box>
            <size>0.01 0.01 0.01</size>
            </box>
          </geometry>
        </collision>
        <visual name="visual">
          <geometry>
            <box>
              <size>0.01 0.01 0.01</size>
            </box>
          </geometry>
          <material>
            <script>
              <uri>file://media/materials/scripts/gazebo.material</uri>
              <name>Gazebo/Black</name>
            </script>
          </material>
        </visual>
      </link>

    <joint name="susp_rear_right_prismatic" type="prismatic">
      <parent>chassis</parent>
      <child>susp_rear_right</child>
      <axis>
        <xyz>0 0 1</xyz>
          <limit>
            <lower>-0.03</lower>
            <upper>0.03</upper>
          </limit>
        <dynamics>
          <friction>1</friction>
          <damping>10</damping>
          <spring_stiffness>150</spring_stiffness>
          <spring_reference>-0.06</spring_reference>
        </dynamics>
      </axis>
      <physics>
        <ode>
          <limit>
            <cfm>0</cfm>
            <erp>0.01</erp>
          </limit>
          <suspension>
            <cfm>0</cfm>
            <erp>0.01</erp>
          </suspension>
        </ode>
      </physics>

    </joint>
      <joint name="susp_rear_left_prismatic" type="prismatic">
        
        <parent>chassis</parent>
        <child>susp_rear_left</child>
        <axis>
        <xyz>0 0 1</xyz>
          <limit>
            <lower>-0.03</lower>
            <upper>0.03</upper>
          </limit>
        <xyz>1 0 0</xyz>
          <limit>
            <lower>0</lower>
            <upper>0</upper>
          </limit>
        <xyz>0 1 0</xyz>
          <limit>
            <lower>0</lower>
            <upper>0</upper>
          </limit>
          <dynamics>
            <friction>1</friction>
            <damping>10</damping>
            <spring_stiffness>150</spring_stiffness>
          <spring_reference>-0.06</spring_reference>
          </dynamics>
        </axis>
      <physics>
        <ode>
          <limit>
            <cfm>0</cfm>
            <erp>0.01</erp>
          </limit>
          <suspension>
            <cfm>0</cfm>
            <erp>0.01</erp>
          </suspension>
        </ode>
      </physics>

      </joint>
      <joint name='wheel_rear_right_spin' type='revolute'>
        <parent>susp_rear_right</parent>

        <child>wheel_rear_right</child>
        <axis>
          <xyz>0 0 1</xyz>
          <limit>
            <lower>-1e+16</lower>
            <upper>1e+16</upper>
          </limit>
          <dynamics>
            <friction>0.004</friction>
            <spring_reference>0</spring_reference>
            <spring_stiffness>0</spring_stiffness>
          </dynamics>
        </axis>
      </joint>


      <joint name='wheel_rear_left_spin' type='revolute'>
        <!-- <parent>chassis</parent> -->
        <parent>susp_rear_left</parent>
        <child>wheel_rear_left</child>
        <axis>
          <xyz>0 0 1</xyz>
          <limit>
            <lower>-1e+16</lower>
            <upper>1e+16</upper>
          </limit>
          <dynamics>
            <friction>0.004</friction>
            <spring_reference>0</spring_reference>
            <spring_stiffness>0</spring_stiffness>
          </dynamics>
        </axis>
      </joint>
    </model>
    

  </world>
</sdf>
